<?xml version="1.0"?>
<robot xmlns:xacro="http://www.ros.org/wiki/xacro" name="MJBot">

    <!-- thickness/radius of model links -->
    <xacro:property name="thickness" value="0.025"/> 
    <xacro:property name="joint_thickness" value="0.035"/> 


    <!-- prismatic link thickness -->
    <xacro:property name="prismatic_link_radius" value="0.012"/>  

    <!-- theta values from the DH table -->
    <xacro:property name="theta1" value="0"/> 
    <xacro:property name="theta2" value="0"/> 
    <xacro:property name="theta4" value="0"/> 

    <!-- d parameter values from the DH table -->
    <xacro:property name="d1" value="0.35"/> 
    <xacro:property name="d2" value="0"/> 
    <xacro:property name="d3" value="0.34"/> 
    <xacro:property name="d4" value="0"/> 

    <!-- a parameter values from the DH table -->
    <xacro:property name="a1" value="0.2"/> 
    <xacro:property name="a2" value="0.2"/> 


    <!-- alpha parameter values from the DH table -->
    <xacro:property name="alpha2" value="3.14"/> 


    

    <!-- mass for inertia definition -->
    <xacro:property name="mass1" value="0.1"/> 

    <!-- inertia definition using macros -->
    <xacro:macro name="default_inertia" params="mass">
        <inertial>
            <mass value="${mass}"/>
            <inertia ixx="0.1" ixy="0.0" ixz="0.0" iyy="0.1" iyz="0.0" izz="0.1"/>
        </inertial>
    </xacro:macro>

    <!-- material definition -->
    <material name="dark_grey">
        <color rgba="0.5 0.5 0.5 1.0"/>
    </material>
    <material name="light_grey">
        <color rgba="0.8 0.8 0.8 1.0"/>
    </material>


    <!-- Gazebo world definition -->
    <link name="world"/>
    <link name="base_link"> 
        <inertial> 
            <origin xyz="0 0 0" rpy="0 0 0"/>   
            <mass value="1"/> 
            <inertia ixx="1.0" ixy="0.0" ixz="0.0" iyy="1.0" iyz="0.0" izz="1.0"/> 
        </inertial>
        <visual>
            <geometry>
            <cylinder radius="0.1" length="0.03"/>
            </geometry>
            <material name="dark_grey"/>
        </visual>
    </link>

    <!-- fixed base joint -->
    <joint name="fixed1" type="fixed">
        <parent link="world"/>
        <child link="base_link"/>
    </joint>


    <!-- First link definition -->
    <link name="tmp_11">
        <xacro:default_inertia mass="${mass1}"/>
        <visual>
            <geometry>
                <cylinder length="${d1}" radius="${thickness}"/>
            </geometry>
            <origin rpy="0 0 0" xyz="0 0 ${d1/2}"/>
            <material name="light_grey"/>
        </visual>
    </link>

    <joint name="base_joint" type="fixed">
        <parent link="base_link"/>
        <child link="tmp_11"/>
        <origin rpy="0 0 0" xyz="0 0 0"/>
    </joint>




    <link name="tmp_12">
        <xacro:default_inertia mass="${mass1}"/>
        <visual>
            <geometry>
                <cylinder length="0.1" radius="${joint_thickness}"/>
            </geometry>
            <origin rpy="0 0 0" xyz="0 0 0"/>
            <material name="dark_grey"/>
        </visual>
    </link>


    <!-- a fixed joint added  to allow us represent the kinematic chain accurately -->
    <joint name="fixed2" type="fixed">
        <parent link="tmp_11"/>
        <child link="tmp_12"/>
        <origin rpy="0 0 0" xyz="0 0 ${d1}"/>
    </joint>


    <!-- first revolute joint -->
    <joint name="theta1_joint" type="revolute">
        <parent link="tmp_12"/>
        <child link="L1"/>
        <axis xyz="0 0 1"/>
        <limit effort="1000.0" lower="-1.57" upper="1.57" velocity="0.5"/>
        <origin rpy="0 0 ${theta1}" xyz="0 0 0"/>
        <dynamics damping="0.7"/>
    </joint>

    <link name="L1">
        <xacro:default_inertia mass="${mass1}"/>
        <visual>
            <geometry>
                <cylinder length="${a1}" radius="${thickness}"/>
            </geometry>
            <origin rpy="0 ${pi/2} 0" xyz="${a1/2} 0 0"/>
            <material name="light_grey"/>
        </visual>
    </link>




    <link name="tmp_13">
        <xacro:default_inertia mass="${mass1}"/>
        <visual>
            <geometry>
                <cylinder length="0.1" radius="0.035"/>
            </geometry>
            <material name="dark_grey"/>
        </visual>
    </link>

    <joint name="a1" type="fixed">
        <parent link="L1"/>
        <child link="tmp_13"/>
        <origin rpy="0 0 0" xyz="${a1} 0 0"/>
    </joint>


    <link name="L2">
        <xacro:default_inertia mass="${mass1}"/>
        <visual>
            <geometry>
                <cylinder radius="${thickness}" length="${a2}"/>
            </geometry>
            <origin xyz="${a2/2} 0.0 0.0" rpy="0.0 ${pi/2} 0.0"/>
            <material name="light_grey"/>
        </visual>
    </link>


    <!-- second joint definition/ second revolute joint -->
    <joint name="theta2_joint" type="revolute">
        <parent link="tmp_13"/>
        <child link="L2"/>
        <axis xyz="0 0 1"/>
        <limit effort="1000.0" lower="-1.57" upper="1.57" velocity="0.5"/>
        <origin rpy="0 0 0" xyz="0 0 0"/>
    </joint>


    <link name="L3">
        <xacro:default_inertia mass="${mass1}"/>
        <visual>
            <geometry>
                <cylinder length="0.1" radius="0.035"/>
            </geometry>
            <material name="dark_grey"/>
        </visual>
    </link>

    <joint name="a2" type="fixed">
        <parent link="L2"/>
        <child link="L3"/>
        <origin rpy="0 0 0" xyz="${a2} 0 0"/>
    </joint>

    <link name="tmp_31">
        <xacro:default_inertia mass="${mass1}"/>
        <visual>
            <geometry>
                <cylinder length="${d3}" radius="${prismatic_link_radius}"/>
            </geometry>
            <origin rpy="0 0 0" xyz="0 0 ${d3/2}"/>
            <material name="light_grey"/>
        </visual>
    </link>


    <!-- third joint definition (the only prismatic joint) -->
    <joint name="d3_joint" type="prismatic">
        <parent link="L3"/>
        <child link="tmp_31"/>
        <axis xyz="0 0 -1"/>
        <limit effort="1000.0" lower="0.06" upper="${d3}" velocity="0.5"/>
        <origin rpy="0 0 0" xyz="0 0 0"/>
    </joint>


    <!-- definition of gripper -->
    <link name="gripper">
        <xacro:default_inertia mass="${mass1}"/>
        <visual>
            <geometry>
            <box size="0.05 0.05 0.01"/>
            </geometry>
            <material name="dark_grey"/>
            <origin xyz="0.0 0.0 0.0" rpy="0.0 0.0 0.0"/>
        </visual>
    </link> 

    <!-- gripper first finger -->
    <link name="gripper_finger1">
        <xacro:default_inertia mass="${mass1}"/>
        <visual>
            <geometry>
            <box size="0.01 0.05 0.05"/>
            </geometry>
            <material name="dark_grey"/>
            <origin xyz="-0.03 0.0 -0.015" rpy="0.0 0.0 0.0"/>
        </visual>
    </link> 
    

    <!-- gripper second finger -->
    <link name="gripper_finger2">
        <xacro:default_inertia mass="${mass1}"/>
        <visual>
            <geometry>
            <box size="0.01 0.05 0.05"/>
            </geometry>
            <material name="dark_grey"/>
            <origin xyz="0.015 0.0 -0.015" rpy="0.0 0.0 0.0"/>
        </visual>
    </link> 


    <!-- fourth joint/ third revolute joint. -->
    <joint name="theta4_joint" type="revolute">
        <parent link="tmp_31"/>
        <child link="gripper"/>
        <axis xyz="0 0 1"/>
        <limit effort="1000.0" lower="-3.1416" upper="3.1416" velocity="0.5"/>
        <origin rpy="0 0 ${theta4}" xyz="0 0 0"/>
    </joint>

    <!-- fixed joints to attach the fingers of the gripper -->
    <joint name="grip_1" type="fixed">
        <parent link="gripper"/>
        <child link="gripper_finger1"/>
        <origin rpy="0 0 0" xyz="0 0 0"/>
    </joint>
    <joint name="grip_2" type="fixed">
        <parent link="gripper"/>
        <child link="gripper_finger2"/>
        <origin rpy="0 0 0" xyz="0.01 0 0"/>
    </joint>



    <!-- Gazebo materials definition -->
    <gazebo reference= "L1">
        <material>Gazebo/Reflection</material>
    </gazebo>
    <gazebo reference= "L2">
        <material>Gazebo/Reflection</material>
    </gazebo>
    <gazebo reference= "L3">
        <material>Gazebo/Black</material>
    </gazebo>
    <gazebo reference= "base_link">
        <material>Gazebo/Black</material>
    </gazebo>
    <gazebo reference= "tmp_11">
        <material>Gazebo/Reflection</material>
    </gazebo>
    <gazebo reference= "tmp_12">
        <material>Gazebo/Black</material>
    </gazebo>
    <gazebo reference= "tmp_13">
        <material>Gazebo/Black</material>
    </gazebo>
    <gazebo reference= "tmp_31">
        <material>Gazebo/Reflection</material>
    </gazebo>
    <gazebo reference= "gripper">
        <material>Gazebo/Cyan</material>
    </gazebo>
    <gazebo reference= "gripper_finger1">
        <material>Gazebo/Cyan</material>
    </gazebo>
    <gazebo reference= "gripper_finger2">
        <material>Gazebo/Cyan</material>
    </gazebo>


  <!-- Gazebo transmission definition -->
  <!-- first joint added to gazebo -->
    <transmission name="theta1_trans">
        <type>transmission_interface/SimpleTransmission</type>
        <joint name="theta1_joint">
            <hardwareInterface>hardware_interface/PositionJointInterface</hardwareInterface>
        </joint>
        <actuator name="theta1_motor">
            <mechanicalReduction>1.0</mechanicalReduction>
            <hardwareInterface>hardware_interface/PositionJointInterface</hardwareInterface>
        </actuator>
    </transmission>

    <!-- second joint added to gazebo -->
    <transmission name="theta2_trans">
        <type>transmission_interface/SimpleTransmission</type>
        <joint name="theta2_joint">
            <hardwareInterface>hardware_interface/PositionJointInterface</hardwareInterface>
        </joint>
        <actuator name="theta2_motor">
            <mechanicalReduction>1.0</mechanicalReduction>
            <hardwareInterface>hardware_interface/PositionJointInterface</hardwareInterface>
        </actuator>
    </transmission>

    <!-- third joint added to gazebo -->
    <transmission name="d3_trans">
        <type>transmission_interface/SimpleTransmission</type>
        <joint name="d3_joint">
            <hardwareInterface>hardware_interface/PositionJointInterface</hardwareInterface>
        </joint>
        <actuator name="d3_motor">
            <mechanicalReduction>1.0</mechanicalReduction>
            <hardwareInterface>hardware_interface/PositionJointInterface</hardwareInterface>
        </actuator>
    </transmission>


    <!-- fourth joint added to gazebo -->
    <transmission name="theta4_trans">
        <type>transmission_interface/SimpleTransmission</type>
        <joint name="theta4_joint">
            <hardwareInterface>hardware_interface/PositionJointInterface</hardwareInterface>
        </joint>
        <actuator name="theta4_motor">
            <mechanicalReduction>1.0</mechanicalReduction>
            <hardwareInterface>hardware_interface/PositionJointInterface</hardwareInterface>
        </actuator>
    </transmission>

  
    <!-- Gazebo plugin for ROS Control -->
    <gazebo>
        <plugin name="gazebo_ros_control" filename="libgazebo_ros_control.so">
            <robotNamespace>MJBot</robotNamespace>
        </plugin>
    </gazebo>

</robot>
